Workbook

Sheet Data
B2: Pre-El Inspection report_ Sep '25
B3: Date | C3: 45901 | D3: 45902 | E3: 45903 | F3: 45904 | G3: 45905 | H3: 45906 | I3: 45907 | J3: 45908 | K3: 45909 | L3: 45910 | M3: 45911 | N3: 45912 | O3: 45913 | P3: 45914 | Q3: 45915 | R3: 45916 | S3: 45917 | T3: 45918 | U3: 45919 | V3: 45920 | W3: 45921 | X3: 45922 | Y3: 45923 | Z3: 45924 | AA3: 45925 | AB3: 45926 | AC3: 45927 | AD3: 45928 | AE3: 45929 | AF3: 45930 | AG3: Month total
B4: Total Production | C4: ='Line - 1'!C4+'Line - 2'!C4 -> 4898 | D4: ='Line - 1'!D4+'Line - 2'!D4 -> 4821 | E4: ='Line - 1'!E4+'Line - 2'!E4 -> 5026 | F4: ='Line - 1'!F4+'Line - 2'!F4 -> 5017 | G4: ='Line - 1'!G4+'Line - 2'!G4 -> 4990 | H4: ='Line - 1'!H4+'Line - 2'!H4 -> 5005 | I4: ='Line - 1'!I4+'Line - 2'!I4 -> 5067 | J4: ='Line - 1'!J4+'Line - 2'!J4 -> 5222 | ... AF4: ='Line - 1'!AF4+'Line - 2'!AF4 -> 0 | AG4: =SUM(C4:AF4) -> 106204
B5: Total rejection | C5: =SUM(C7:C14) -> 450 | D5: =SUM(D7:D14) -> 467 | E5: =SUM(E7:E14) -> 435 | F5: =SUM(F7:F14) -> 429 | G5: =SUM(G7:G14) -> 428 | H5: =SUM(H7:H14) -> 449 | I5: =SUM(I7:I14) -> 456 | J5: =SUM(J7:J14) -> 489 | ... AG5: =SUM(AG7:AG14) -> 9115
B6: Rejection % | C6: =IF(C4=0,0,(C5/C4)) -> 0.091874234 | D6: =IF(D4=0,0,(D5/D4)) -> 0.09686787 | E6: =IF(E4=0,0,(E5/E4)) -> 0.08654994 | F6: =IF(F4=0,0,(F5/F4)) -> 0.085509268 | G6: =IF(G4=0,0,(G5/G4)) -> 0.085771543 | H6: =IF(H4=0,0,(H5/H4)) -> 0.08971029 | I6: =IF(I4=0,0,(I5/I4)) -> 0.089994079 | J6: =IF(J4=0,0,(J5/J4)) -> 0.093642283 | ... AG6: =IF(AG4=0,0,(AG5/AG4)) -> 0.085825393
B7: Micro Crack | C7: ='Line - 1'!C7+'Line - 2'!C7 -> 57 | D7: ='Line - 1'!D7+'Line - 2'!D7 -> 73 | E7: ='Line - 1'!E7+'Line - 2'!E7 -> 54 | F7: ='Line - 1'!F7+'Line - 2'!F7 -> 67 | G7: ='Line - 1'!G7+'Line - 2'!G7 -> 58 | H7: ='Line - 1'!H7+'Line - 2'!H7 -> 65 | I7: ='Line - 1'!I7+'Line - 2'!I7 -> 72 | J7: ='Line - 1'!J7+'Line - 2'!J7 -> 76 | ... AF7: ='Line - 1'!AF7+'Line - 2'!AF7 -> 0 | AG7: =+SUM(C7:AF7) -> 1335
B8: Dead Cell | C8: ='Line - 1'!C8+'Line - 2'!C8 -> 3 | D8: ='Line - 1'!D8+'Line - 2'!D8 -> 1 | E8: ='Line - 1'!E8+'Line - 2'!E8 -> 2 | F8: ='Line - 1'!F8+'Line - 2'!F8 -> 6 | G8: ='Line - 1'!G8+'Line - 2'!G8 -> 4 | H8: ='Line - 1'!H8+'Line - 2'!H8 -> 3 | I8: ='Line - 1'!I8+'Line - 2'!I8 -> 0 | J8: ='Line - 1'!J8+'Line - 2'!J8 -> 8 | ... AF8: ='Line - 1'!AF8+'Line - 2'!AF8 -> 0 | AG8: =+SUM(C8:AF8) -> 61
B9: Dry Soldering | C9: ='Line - 1'!C9+'Line - 2'!C9 -> 287 | D9: ='Line - 1'!D9+'Line - 2'!D9 -> 273 | E9: ='Line - 1'!E9+'Line - 2'!E9 -> 289 | F9: ='Line - 1'!F9+'Line - 2'!F9 -> 261 | G9: ='Line - 1'!G9+'Line - 2'!G9 -> 270 | H9: ='Line - 1'!H9+'Line - 2'!H9 -> 262 | I9: ='Line - 1'!I9+'Line - 2'!I9 -> 240 | J9: ='Line - 1'!J9+'Line - 2'!J9 -> 251 | ... AF9: ='Line - 1'!AF9+'Line - 2'!AF9 -> 0 | AG9: =+SUM(C9:AF9) -> 5316
B10: Poor Soldering | C10: ='Line - 1'!C10+'Line - 2'!C10 -> 0 | D10: ='Line - 1'!D10+'Line - 2'!D10 -> 0 | E10: ='Line - 1'!E10+'Line - 2'!E10 -> 0 | F10: ='Line - 1'!F10+'Line - 2'!F10 -> 0 | G10: ='Line - 1'!G10+'Line - 2'!G10 -> 0 | H10: ='Line - 1'!H10+'Line - 2'!H10 -> 0 | I10: ='Line - 1'!I10+'Line - 2'!I10 -> 0 | J10: ='Line - 1'!J10+'Line - 2'!J10 -> 0 | ... AF10: ='Line - 1'!AF10+'Line - 2'!AF10 -> 0 | AG10: =+SUM(C10:AF10) -> 0
B11: Cross Crack | C11: ='Line - 1'!C11+'Line - 2'!C11 -> 42 | D11: ='Line - 1'!D11+'Line - 2'!D11 -> 47 | E11: ='Line - 1'!E11+'Line - 2'!E11 -> 37 | F11: ='Line - 1'!F11+'Line - 2'!F11 -> 37 | G11: ='Line - 1'!G11+'Line - 2'!G11 -> 33 | H11: ='Line - 1'!H11+'Line - 2'!H11 -> 47 | I11: ='Line - 1'!I11+'Line - 2'!I11 -> 56 | J11: ='Line - 1'!J11+'Line - 2'!J11 -> 51 | ... AF11: ='Line - 1'!AF11+'Line - 2'!AF11 -> 0 | AG11: =+SUM(C11:AF11) -> 901
B12: Grid Defect | C12: ='Line - 1'!C12+'Line - 2'!C12 -> 18 | D12: ='Line - 1'!D12+'Line - 2'!D12 -> 13 | E12: ='Line - 1'!E12+'Line - 2'!E12 -> 11 | F12: ='Line - 1'!F12+'Line - 2'!F12 -> 7 | G12: ='Line - 1'!G12+'Line - 2'!G12 -> 16 | H12: ='Line - 1'!H12+'Line - 2'!H12 -> 9 | I12: ='Line - 1'!I12+'Line - 2'!I12 -> 20 | J12: ='Line - 1'!J12+'Line - 2'!J12 -> 34 | ... AF12: ='Line - 1'!AF12+'Line - 2'!AF12 -> 0 | AG12: =+SUM(C12:AF12) -> 359
B13: Visual Crack | C13: ='Line - 1'!C13+'Line - 2'!C13 -> 41 | D13: ='Line - 1'!D13+'Line - 2'!D13 -> 59 | E13: ='Line - 1'!E13+'Line - 2'!E13 -> 40 | F13: ='Line - 1'!F13+'Line - 2'!F13 -> 50 | G13: ='Line - 1'!G13+'Line - 2'!G13 -> 46 | H13: ='Line - 1'!H13+'Line - 2'!H13 -> 59 | I13: ='Line - 1'!I13+'Line - 2'!I13 -> 65 | J13: ='Line - 1'!J13+'Line - 2'!J13 -> 65 | ... AF13: ='Line - 1'!AF13+'Line - 2'!AF13 -> 0 | AG13: =+SUM(C13:AF13) -> 1086
B14: Dark Area | C14: ='Line - 1'!C14+'Line - 2'!C14 -> 2 | D14: ='Line - 1'!D14+'Line - 2'!D14 -> 1 | E14: ='Line - 1'!E14+'Line - 2'!E14 -> 2 | F14: ='Line - 1'!F14+'Line - 2'!F14 -> 1 | G14: ='Line - 1'!G14+'Line - 2'!G14 -> 1 | H14: ='Line - 1'!H14+'Line - 2'!H14 -> 4 | I14: ='Line - 1'!I14+'Line - 2'!I14 -> 3 | J14: ='Line - 1'!J14+'Line - 2'!J14 -> 4 | ... AF14: ='Line - 1'!AF14+'Line - 2'!AF14 -> 0 | AG14: =+SUM(C14:AF14) -> 57
B16: Visual Inspection report_ Sep '25
B17: Date | C17: 45901 | D17: 45902 | E17: 45903 | F17: 45904 | G17: 45905 | H17: 45906 | I17: 45907 | J17: 45908 | K17: 45909 | L17: 45910 | M17: 45911 | N17: 45912 | O17: 45913 | P17: 45914 | Q17: 45915 | R17: 45916 | S17: 45917 | T17: 45918 | U17: 45919 | V17: 45920 | W17: 45921 | X17: 45922 | Y17: 45923 | Z17: 45924 | AA17: 45925 | AB17: 45926 | AC17: 45927 | AD17: 45928 | AE17: 45929 | AF17: 45930 | AG17: Month total
B18: Total Production | C18: ='Line - 1'!C18+'Line - 2'!C18 -> 4898 | D18: ='Line - 1'!D18+'Line - 2'!D18 -> 4821 | E18: ='Line - 1'!E18+'Line - 2'!E18 -> 5026 | F18: ='Line - 1'!F18+'Line - 2'!F18 -> 5017 | G18: ='Line - 1'!G18+'Line - 2'!G18 -> 4990 | H18: ='Line - 1'!H18+'Line - 2'!H18 -> 5005 | I18: ='Line - 1'!I18+'Line - 2'!I18 -> 5067 | J18: ='Line - 1'!J18+'Line - 2'!J18 -> 5222 | ... AF18: ='Line - 1'!AF18+'Line - 2'!AF18 -> 0 | AG18: =SUM(C18:AF18) -> 106204
B19: Total rejection | C19: =SUM(C21:C33) -> 189 | D19: =SUM(D21:D33) -> 209 | E19: =SUM(E21:E33) -> 259 | F19: =SUM(F21:F33) -> 242 | G19: =SUM(G21:G33) -> 261 | H19: =SUM(H21:H33) -> 227 | I19: =SUM(I21:I33) -> 248 | J19: =SUM(J21:J33) -> 242 | ... AG19: =SUM(AG21:AG33) -> 4086
A20: % | B20: Rejection % | C20: =IF(C18=0,0,(C19/C18)) -> 0.038587178 | D20: =IF(D18=0,0,(D19/D18)) -> 0.043352002 | E20: =IF(E18=0,0,(E19/E18)) -> 0.051532033 | F20: =IF(F18=0,0,(F19/F18)) -> 0.048235998 | G20: =IF(G18=0,0,(G19/G18)) -> 0.052304609 | H20: =IF(H18=0,0,(H19/H18)) -> 0.045354645 | I20: =IF(I18=0,0,(I19/I18)) -> 0.048944148 | J20: =IF(J18=0,0,(J19/J18)) -> 0.046342398 | ... AG20: =IF(AG18=0,0,(AG19/AG18)) -> 0.038473127
B21: Misalignment | C21: ='Line - 1'!C21+'Line - 2'!C21 -> 5 | D21: ='Line - 1'!D21+'Line - 2'!D21 -> 0 | E21: ='Line - 1'!E21+'Line - 2'!E21 -> 1 | F21: ='Line - 1'!F21+'Line - 2'!F21 -> 0 | G21: ='Line - 1'!G21+'Line - 2'!G21 -> 3 | H21: ='Line - 1'!H21+'Line - 2'!H21 -> 2 | I21: ='Line - 1'!I21+'Line - 2'!I21 -> 1 | J21: ='Line - 1'!J21+'Line - 2'!J21 -> 9 | ... AF21: ='Line - 1'!AF21+'Line - 2'!AF21 -> 0 | AG21: =+SUM(C21:AF21) -> 39
B22: Cell To Cell Touch | C22: ='Line - 1'!C22+'Line - 2'!C22 -> 11 | D22: ='Line - 1'!D22+'Line - 2'!D22 -> 8 | E22: ='Line - 1'!E22+'Line - 2'!E22 -> 17 | F22: ='Line - 1'!F22+'Line - 2'!F22 -> 32 | G22: ='Line - 1'!G22+'Line - 2'!G22 -> 13 | H22: ='Line - 1'!H22+'Line - 2'!H22 -> 12 | I22: ='Line - 1'!I22+'Line - 2'!I22 -> 3 | J22: ='Line - 1'!J22+'Line - 2'!J22 -> 5 | ... AF22: ='Line - 1'!AF22+'Line - 2'!AF22 -> 0 | AG22: =+SUM(C22:AF22) -> 303
B23: Chipping | C23: ='Line - 1'!C23+'Line - 2'!C23 -> 1 | D23: ='Line - 1'!D23+'Line - 2'!D23 -> 3 | E23: ='Line - 1'!E23+'Line - 2'!E23 -> 1 | F23: ='Line - 1'!F23+'Line - 2'!F23 -> 3 | G23: ='Line - 1'!G23+'Line - 2'!G23 -> 0 | H23: ='Line - 1'!H23+'Line - 2'!H23 -> 0 | I23: ='Line - 1'!I23+'Line - 2'!I23 -> 3 | J23: ='Line - 1'!J23+'Line - 2'!J23 -> 0 | ... AF23: ='Line - 1'!AF23+'Line - 2'!AF23 -> 0 | AG23: =+SUM(C23:AF23) -> 60
B24: Tabbing Missing | C24: ='Line - 1'!C24+'Line - 2'!C24 -> 91 | D24: ='Line - 1'!D24+'Line - 2'!D24 -> 126 | E24: ='Line - 1'!E24+'Line - 2'!E24 -> 167 | F24: ='Line - 1'!F24+'Line - 2'!F24 -> 126 | G24: ='Line - 1'!G24+'Line - 2'!G24 -> 153 | H24: ='Line - 1'!H24+'Line - 2'!H24 -> 168 | I24: ='Line - 1'!I24+'Line - 2'!I24 -> 162 | J24: ='Line - 1'!J24+'Line - 2'!J24 -> 145 | ... AF24: ='Line - 1'!AF24+'Line - 2'!AF24 -> 0 | AG24: =+SUM(C24:AF24) -> 2261
B25: Cell Scratch | C25: ='Line - 1'!C25+'Line - 2'!C25 -> 7 | D25: ='Line - 1'!D25+'Line - 2'!D25 -> 14 | E25: ='Line - 1'!E25+'Line - 2'!E25 -> 15 | F25: ='Line - 1'!F25+'Line - 2'!F25 -> 18 | G25: ='Line - 1'!G25+'Line - 2'!G25 -> 7 | H25: ='Line - 1'!H25+'Line - 2'!H25 -> 8 | I25: ='Line - 1'!I25+'Line - 2'!I25 -> 16 | J25: ='Line - 1'!J25+'Line - 2'!J25 -> 7 | ... AF25: ='Line - 1'!AF25+'Line - 2'!AF25 -> 0 | AG25: =+SUM(C25:AF25) -> 220
B26: EVA Spot | C26: ='Line - 1'!C26+'Line - 2'!C26 -> 0 | D26: ='Line - 1'!D26+'Line - 2'!D26 -> 1 | E26: ='Line - 1'!E26+'Line - 2'!E26 -> 0 | F26: ='Line - 1'!F26+'Line - 2'!F26 -> 1 | G26: ='Line - 1'!G26+'Line - 2'!G26 -> 2 | H26: ='Line - 1'!H26+'Line - 2'!H26 -> 0 | I26: ='Line - 1'!I26+'Line - 2'!I26 -> 0 | J26: ='Line - 1'!J26+'Line - 2'!J26 -> 0 | ... AF26: ='Line - 1'!AF26+'Line - 2'!AF26 -> 0 | AG26: =+SUM(C26:AF26) -> 7
B27: Spot On Cell | C27: ='Line - 1'!C27+'Line - 2'!C27 -> 10 | D27: ='Line - 1'!D27+'Line - 2'!D27 -> 13 | E27: ='Line - 1'!E27+'Line - 2'!E27 -> 13 | F27: ='Line - 1'!F27+'Line - 2'!F27 -> 9 | G27: ='Line - 1'!G27+'Line - 2'!G27 -> 8 | H27: ='Line - 1'!H27+'Line - 2'!H27 -> 2 | I27: ='Line - 1'!I27+'Line - 2'!I27 -> 8 | J27: ='Line - 1'!J27+'Line - 2'!J27 -> 5 | ... AF27: ='Line - 1'!AF27+'Line - 2'!AF27 -> 0 | AG27: =+SUM(C27:AF27) -> 163
B28: Ribbon Bend | C28: ='Line - 1'!C28+'Line - 2'!C28 -> 5 | D28: ='Line - 1'!D28+'Line - 2'!D28 -> 7 | E28: ='Line - 1'!E28+'Line - 2'!E28 -> 2 | F28: ='Line - 1'!F28+'Line - 2'!F28 -> 2 | G28: ='Line - 1'!G28+'Line - 2'!G28 -> 4 | H28: ='Line - 1'!H28+'Line - 2'!H28 -> 1 | I28: ='Line - 1'!I28+'Line - 2'!I28 -> 2 | J28: ='Line - 1'!J28+'Line - 2'!J28 -> 5 | ... AF28: ='Line - 1'!AF28+'Line - 2'!AF28 -> 0 | AG28: =+SUM(C28:AF28) -> 94
B29: String To String Gap | C29: ='Line - 1'!C29+'Line - 2'!C29 -> 6 | D29: ='Line - 1'!D29+'Line - 2'!D29 -> 6 | E29: ='Line - 1'!E29+'Line - 2'!E29 -> 7 | F29: ='Line - 1'!F29+'Line - 2'!F29 -> 12 | G29: ='Line - 1'!G29+'Line - 2'!G29 -> 6 | H29: ='Line - 1'!H29+'Line - 2'!H29 -> 1 | I29: ='Line - 1'!I29+'Line - 2'!I29 -> 12 | J29: ='Line - 1'!J29+'Line - 2'!J29 -> 22 | ... AF29: ='Line - 1'!AF29+'Line - 2'!AF29 -> 0 | AG29: =+SUM(C29:AF29) -> 196
B30: Ribbon Missing | C30: ='Line - 1'!C30+'Line - 2'!C30 -> 12 | D30: ='Line - 1'!D30+'Line - 2'!D30 -> 2 | E30: ='Line - 1'!E30+'Line - 2'!E30 -> 5 | F30: ='Line - 1'!F30+'Line - 2'!F30 -> 5 | G30: ='Line - 1'!G30+'Line - 2'!G30 -> 16 | H30: ='Line - 1'!H30+'Line - 2'!H30 -> 7 | I30: ='Line - 1'!I30+'Line - 2'!I30 -> 6 | J30: ='Line - 1'!J30+'Line - 2'!J30 -> 2 | ... AF30: ='Line - 1'!AF30+'Line - 2'!AF30 -> 0 | AG30: =+SUM(C30:AF30) -> 133
B31: Extra Cell | C31: ='Line - 1'!C31+'Line - 2'!C31 -> 9 | D31: ='Line - 1'!D31+'Line - 2'!D31 -> 9 | E31: ='Line - 1'!E31+'Line - 2'!E31 -> 8 | F31: ='Line - 1'!F31+'Line - 2'!F31 -> 8 | G31: ='Line - 1'!G31+'Line - 2'!G31 -> 3 | H31: ='Line - 1'!H31+'Line - 2'!H31 -> 8 | I31: ='Line - 1'!I31+'Line - 2'!I31 -> 11 | J31: ='Line - 1'!J31+'Line - 2'!J31 -> 15 | ... AF31: ='Line - 1'!AF31+'Line - 2'!AF31 -> 0 | AG31: =+SUM(C31:AF31) -> 164
B32: Extra Ribbon | C32: ='Line - 1'!C32+'Line - 2'!C32 -> 4 | D32: ='Line - 1'!D32+'Line - 2'!D32 -> 4 | E32: ='Line - 1'!E32+'Line - 2'!E32 -> 2 | F32: ='Line - 1'!F32+'Line - 2'!F32 -> 3 | G32: ='Line - 1'!G32+'Line - 2'!G32 -> 5 | H32: ='Line - 1'!H32+'Line - 2'!H32 -> 3 | I32: ='Line - 1'!I32+'Line - 2'!I32 -> 6 | J32: ='Line - 1'!J32+'Line - 2'!J32 -> 3 | ... AF32: ='Line - 1'!AF32+'Line - 2'!AF32 -> 0 | AG32: =+SUM(C32:AF32) -> 55
B33: Dust | C33: ='Line - 1'!C33+'Line - 2'!C33 -> 28 | D33: ='Line - 1'!D33+'Line - 2'!D33 -> 16 | E33: ='Line - 1'!E33+'Line - 2'!E33 -> 21 | F33: ='Line - 1'!F33+'Line - 2'!F33 -> 23 | G33: ='Line - 1'!G33+'Line - 2'!G33 -> 41 | H33: ='Line - 1'!H33+'Line - 2'!H33 -> 15 | I33: ='Line - 1'!I33+'Line - 2'!I33 -> 18 | J33: ='Line - 1'!J33+'Line - 2'!J33 -> 24 | ... AF33: ='Line - 1'!AF33+'Line - 2'!AF33 -> 0 | AG33: =+SUM(C33:AF33) -> 391
B36: Lam-QC Inspection report_Sep '25
B37: Date | C37: 45901 | D37: 45902 | E37: 45903 | F37: 45904 | G37: 45905 | H37: 45906 | I37: 45907 | J37: 45908 | K37: 45909 | L37: 45910 | M37: 45911 | N37: 45912 | O37: 45913 | P37: 45914 | Q37: 45915 | R37: 45916 | S37: 45917 | T37: 45918 | U37: 45919 | V37: 45920 | W37: 45921 | X37: 45922 | Y37: 45923 | Z37: 45924 | AA37: 45925 | AB37: 45926 | AC37: 45927 | AD37: 45928 | AE37: 45929 | AF37: 45930 | AG37: Month total
B38: Total Production | C38: ='Line - 1'!C38+'Line - 2'!C38 -> 4970 | D38: ='Line - 1'!D38+'Line - 2'!D38 -> 4796 | E38: ='Line - 1'!E38+'Line - 2'!E38 -> 4959 | F38: ='Line - 1'!F38+'Line - 2'!F38 -> 4950 | G38: ='Line - 1'!G38+'Line - 2'!G38 -> 5007 | H38: ='Line - 1'!H38+'Line - 2'!H38 -> 4977 | I38: ='Line - 1'!I38+'Line - 2'!I38 -> 4991 | J38: ='Line - 1'!J38+'Line - 2'!J38 -> 5287 | ... AF38: ='Line - 1'!AF38+'Line - 2'!AF38 -> 0 | AG38: =SUM(C38:AF38) -> 106046
B39: Total rejection | C39: =SUM(C41:C67) -> 39 | D39: =SUM(D41:D67) -> 31 | E39: =SUM(E41:E67) -> 34 | F39: =SUM(F41:F67) -> 30 | G39: =SUM(G41:G67) -> 36 | H39: =SUM(H41:H67) -> 29 | I39: =SUM(I41:I67) -> 33 | J39: =SUM(J41:J67) -> 33 | ... AG39: =SUM(AG41:AG67) -> #REF!
A40: % | B40: Rejection % | C40: =IF(C38=0,0,(C39/C38)) -> 0.0078470825 | D40: =IF(D38=0,0,(D39/D38)) -> 0.0064637198 | E40: =IF(E38=0,0,(E39/E38)) -> 0.006856221 | F40: =IF(F38=0,0,(F39/F38)) -> 0.0060606061 | G40: =IF(G38=0,0,(G39/G38)) -> 0.0071899341 | H40: =IF(H38=0,0,(H39/H38)) -> 0.0058268033 | I40: =IF(I38=0,0,(I39/I38)) -> 0.0066119014 | J40: =IF(J38=0,0,(J39/J38)) -> 0.006241725 | ... AG40: =IF(AG38=0,0,(AG39/AG38)) -> #REF!
B41: Bubbles On Cell | C41: ='Line - 1'!C41+'Line - 2'!C41 -> 28 | D41: ='Line - 1'!D41+'Line - 2'!D41 -> 9 | E41: ='Line - 1'!E41+'Line - 2'!E41 -> 9 | F41: ='Line - 1'!F41+'Line - 2'!F41 -> 2 | G41: ='Line - 1'!G41+'Line - 2'!G41 -> 5 | H41: ='Line - 1'!H41+'Line - 2'!H41 -> 4 | I41: ='Line - 1'!I41+'Line - 2'!I41 -> 10 | J41: ='Line - 1'!J41+'Line - 2'!J41 -> 8 | ... AF41: ='Line - 1'!AF41+'Line - 2'!AF41 -> 0 | AG41: =+SUM(C41:AF41) -> 171
B42: Barcode Bubbles | C42: ='Line - 1'!C42+'Line - 2'!C42 -> 0 | D42: ='Line - 1'!D42+'Line - 2'!D42 -> 0 | E42: ='Line - 1'!E42+'Line - 2'!E42 -> 0 | F42: ='Line - 1'!F42+'Line - 2'!F42 -> 2 | G42: ='Line - 1'!G42+'Line - 2'!G42 -> 0 | H42: ='Line - 1'!H42+'Line - 2'!H42 -> 0 | I42: ='Line - 1'!I42+'Line - 2'!I42 -> 0 | J42: ='Line - 1'!J42+'Line - 2'!J42 -> 0 | ... AF42: ='Line - 1'!AF42+'Line - 2'!AF42 -> 0 | AG42: =+SUM(C42:AF42) -> 2
B43: Cell Cutting | C43: ='Line - 1'!C43+'Line - 2'!C43 -> 0 | D43: ='Line - 1'!D43+'Line - 2'!D43 -> 0 | E43: ='Line - 1'!E43+'Line - 2'!E43 -> 0 | F43: ='Line - 1'!F43+'Line - 2'!F43 -> 0 | G43: ='Line - 1'!G43+'Line - 2'!G43 -> 0 | H43: ='Line - 1'!H43+'Line - 2'!H43 -> 0 | I43: ='Line - 1'!I43+'Line - 2'!I43 -> 0 | J43: ='Line - 1'!J43+'Line - 2'!J43 -> 0 | ... AF43: ='Line - 1'!AF43+'Line - 2'!AF43 -> 0 | AG43: =+SUM(C43:AF43) -> 4
B44: Cell To Cell Touch | C44: ='Line - 1'!C44+'Line - 2'!C44 -> 1 | D44: ='Line - 1'!D44+'Line - 2'!D44 -> 2 | E44: ='Line - 1'!E44+'Line - 2'!E44 -> 5 | F44: ='Line - 1'!F44+'Line - 2'!F44 -> 4 | G44: ='Line - 1'!G44+'Line - 2'!G44 -> 0 | H44: ='Line - 1'!H44+'Line - 2'!H44 -> 0 | I44: ='Line - 1'!I44+'Line - 2'!I44 -> 1 | J44: ='Line - 1'!J44+'Line - 2'!J44 -> 1 | ... AF44: ='Line - 1'!AF44+'Line - 2'!AF44 -> 0 | AG44: =+SUM(C44:AF44) -> 32
...

Sheet Trend.
A1: 0
A2: 0 | B2: Pre-lam Rejection %
A3: 0 | B3: Date | C3: 45901 | D3: 45902 | E3: 45903 | F3: 45904 | G3: 45905 | H3: 45906 | I3: 45907 | J3: 45908 | K3: 45909 | L3: 45910 | M3: 45911 | N3: 45912 | O3: 45913 | P3: 45914 | Q3: 45915 | R3: 45916 | S3: 45917 | T3: 45918 | U3: 45919 | V3: 45920 | W3: 45921 | X3: 45922 | Y3: 45923 | Z3: 45924 | AA3: 45925 | AB3: 45926 | AC3: 45927 | AD3: 45928 | AE3: 45929 | AF3: 45930
A4: 0 | B4: Target | C4: 0.1 | D4: 0.1 | E4: 0.1 | F4: 0.1 | G4: 0.1 | H4: 0.1 | I4: 0.1 | J4: 0.1 | K4: 0.1 | L4: 0.1 | M4: 0.1 | N4: 0.1 | O4: 0.1 | P4: 0.1 | Q4: 0.1 | R4: 0.1 | S4: 0.1 | T4: 0.1 | U4: 0.1 | V4: 0.1 | W4: 0.1 | X4: 0.1 | Y4: 0.1 | Z4: 0.1 | AA4: 0.1 | AB4: 0.1 | AC4: 0.1 | AD4: 0.1 | AE4: 0.1 | AF4: 0.1
A5: 0 | B5: Rej. % | C5: =SUM(Data!C6+Data!C20) -> 0.13046141 | D5: =SUM(Data!D6+Data!D20) -> 0.14021987 | E5: =SUM(Data!E6+Data!E20) -> 0.13808197 | F5: =SUM(Data!F6+Data!F20) -> 0.13374527 | G5: =SUM(Data!G6+Data!G20) -> 0.13807615 | H5: =SUM(Data!H6+Data!H20) -> 0.13506494 | I5: =SUM(Data!I6+Data!I20) -> 0.13893823 | J5: =SUM(Data!J6+Data!J20) -> 0.13998468 | ... AF5: =SUM(Data!AF6+Data!AF20) -> 0
A6: 0
A7: 0
A8: 0 | B8: Lam-QC Rejection %
A9: 0 | B9: Date | C9: 45901 | D9: 45902 | E9: 45903 | F9: 45904 | G9: 45905 | H9: 45906 | I9: 45907 | J9: 45908 | K9: 45909 | L9: 45910 | M9: 45911 | N9: 45912 | O9: 45913 | P9: 45914 | Q9: 45915 | R9: 45916 | S9: 45917 | T9: 45918 | U9: 45919 | V9: 45920 | W9: 45921 | X9: 45922 | Y9: 45923 | Z9: 45924 | AA9: 45925 | AB9: 45926 | AC9: 45927 | AD9: 45928 | AE9: 45929 | AF9: 45930
A10: 0 | B10: Target | C10: 0.01 | D10: 0.01 | E10: 0.01 | F10: 0.01 | G10: 0.01 | H10: 0.01 | I10: 0.01 | J10: 0.01 | K10: 0.01 | L10: 0.01 | M10: 0.01 | N10: 0.01 | O10: 0.01 | P10: 0.01 | Q10: 0.01 | R10: 0.01 | S10: 0.01 | T10: 0.01 | U10: 0.01 | V10: 0.01 | W10: 0.01 | X10: 0.01 | Y10: 0.01 | Z10: 0.01 | AA10: 0.01 | AB10: 0.01 | AC10: 0.01 | AD10: 0.01 | AE10: 0.01 | AF10: 0.01
A11: 0 | B11: rejection % | C11: =Data!C40 -> 0.0078470825 | D11: =Data!D40 -> 0.0064637198 | E11: =Data!E40 -> 0.006856221 | F11: =Data!F40 -> 0.0060606061 | G11: =Data!G40 -> 0.0071899341 | H11: =Data!H40 -> 0.0058268033 | I11: =Data!I40 -> 0.0066119014 | J11: =Data!J40 -> 0.006241725 | ... AF11: =Data!AF40 -> 0
A14: 0 | B14: FQC Rejection %
A15: 0 | B15: Date | C15: 45901 | D15: 45902 | E15: 45903 | F15: 45904 | G15: 45905 | H15: 45906 | I15: 45907 | J15: 45908 | K15: 45909 | L15: 45910 | M15: 45911 | N15: 45912 | O15: 45913 | P15: 45914 | Q15: 45915 | R15: 45916 | S15: 45917 | T15: 45918 | U15: 45919 | V15: 45920 | W15: 45921 | X15: 45922 | Y15: 45923 | Z15: 45924 | AA15: 45925 | AB15: 45926 | AC15: 45927 | AD15: 45928 | AE15: 45929 | AF15: 45930
A16: 0 | B16: Target | C16: 0.01 | D16: 0.01 | E16: 0.01 | F16: 0.01 | G16: 0.01 | H16: 0.01 | I16: 0.01 | J16: 0.01 | K16: 0.01 | L16: 0.01 | M16: 0.01 | N16: 0.01 | O16: 0.01 | P16: 0.01 | Q16: 0.01 | R16: 0.01 | S16: 0.01 | T16: 0.01 | U16: 0.01 | V16: 0.01 | W16: 0.01 | X16: 0.01 | Y16: 0.01 | Z16: 0.01 | AA16: 0.01 | AB16: 0.01 | AC16: 0.01 | AD16: 0.01 | AE16: 0.01 | AF16: 0.01
A17: 0 | B17: rejection % | C17: =Data!C74 -> 0.0073829415 | D17: =Data!D74 -> 0.0078756477 | E17: =Data!E74 -> 0.0060617912 | F17: =Data!F74 -> 0.0088422784 | G17: =Data!G74 -> 0.0043903412 | H17: =Data!H74 -> 0.0057518488 | I17: =Data!I74 -> 0.0053835801 | J17: =Data!J74 -> 0.0055769231 | ... AF17: =Data!AF74 -> 0

Sheet Line - 1
B2: Pre-El Inspection report_ Sep '25
B3: Date | C3: 45901 | D3: 45902 | E3: 45903 | F3: 45904 | G3: 45905 | H3: 45906 | I3: 45907 | J3: 45908 | K3: 45909 | L3: 45910 | M3: 45911 | N3: 45912 | O3: 45913 | P3: 45914 | Q3: 45915 | R3: 45916 | S3: 45917 | T3: 45918 | U3: 45919 | V3: 45920 | W3: 45921 | X3: 45922 | Y3: 45923 | Z3: 45924 | AA3: 45925 | AB3: 45926 | AC3: 45927 | AD3: 45928 | AE3: 45929 | AF3: 45930 | AG3: Month total
B4: Total Production | C4: 2222 | D4: 2277 | E4: 2264 | F4: 2292 | G4: 2389 | H4: 2383 | I4: 2372 | J4: 2514 | K4: 2518 | L4: 1891 | M4: 2315 | N4: 2584 | O4: 2529 | P4: 2499 | Q4: 2612 | R4: 2114 | S4: 0 | T4: 2115 | U4: 2386 | V4: 2381 | W4: 2626 | X4: 2486 | AG4: =SUM(C4:AF4) -> 49769
B5: Total rejection | C5: =SUM(C7:C14) -> 215 | D5: =SUM(D7:D14) -> 225 | E5: =SUM(E7:E14) -> 239 | F5: =SUM(F7:F14) -> 230 | G5: =SUM(G7:G14) -> 212 | H5: =SUM(H7:H14) -> 211 | I5: =SUM(I7:I14) -> 200 | J5: =SUM(J7:J14) -> 252 | ... AG5: =SUM(AG7:AG14) -> 4489
B6: Rejection % | C6: =IF(C4=0,0,(C5/C4)) -> 0.096759676 | D6: =IF(D4=0,0,(D5/D4)) -> 0.098814229 | E6: =IF(E4=0,0,(E5/E4)) -> 0.10556537 | F6: =IF(F4=0,0,(F5/F4)) -> 0.10034904 | G6: =IF(G4=0,0,(G5/G4)) -> 0.088740059 | H6: =IF(H4=0,0,(H5/H4)) -> 0.088543852 | I6: =IF(I4=0,0,(I5/I4)) -> 0.084317032 | J6: =IF(J4=0,0,(J5/J4)) -> 0.10023866 | ... AG6: =IF(AG4=0,0,(AG5/AG4)) -> 0.090196709
B7: Micro Crack | C7: 28 | D7: 41 | E7: 29 | F7: 47 | G7: 31 | H7: 45 | I7: 41 | J7: 44 | K7: 32 | L7: 23 | M7: 36 | N7: 45 | O7: 28 | P7: 31 | Q7: 44 | R7: 29 | S7: 0 | T7: 42 | U7: 34 | V7: 28 | W7: 23 | X7: 38 | AG7: =+SUM(C7:AF7) -> 739
B8: Dead Cell | C8: 3 | D8: 0 | E8: 1 | F8: 3 | G8: 2 | H8: 0 | I8: 0 | J8: 2 | K8: 1 | L8: 1 | M8: 1 | N8: 1 | O8: 0 | P8: 0 | Q8: 3 | R8: 0 | S8: 0 | T8: 2 | U8: 3 | V8: 2 | W8: 0 | X8: 1 | AG8: =+SUM(C8:AF8) -> 26
B9: Dry Soldering | C9: 128 | D9: 115 | E9: 159 | F9: 131 | G9: 130 | H9: 114 | I9: 87 | J9: 109 | K9: 127 | L9: 108 | M9: 82 | N9: 102 | O9: 95 | P9: 111 | Q9: 141 | R9: 128 | S9: 0 | T9: 106 | U9: 113 | V9: 99 | W9: 115 | X9: 116 | AG9: =+SUM(C9:AF9) -> 2416
B10: Poor Soldering | C10: 0 | D10: 0 | E10: 0 | F10: 0 | G10: 0 | H10: 0 | I10: 0 | J10: 0 | K10: 0 | L10: 0 | M10: 0 | N10: 0 | O10: 0 | P10: 0 | Q10: 0 | R10: 0 | S10: 0 | T10: 0 | U10: 0 | V10: 0 | W10: 0 | X10: 0 | AG10: =+SUM(C10:AF10) -> 0
B11: Cross Crack | C11: 21 | D11: 22 | E11: 17 | F11: 17 | G11: 17 | H11: 18 | I11: 27 | J11: 30 | K11: 17 | L11: 17 | M11: 12 | N11: 28 | O11: 19 | P11: 21 | Q11: 27 | R11: 30 | S11: 0 | T11: 17 | U11: 17 | V11: 20 | W11: 17 | X11: 30 | AG11: =+SUM(C11:AF11) -> 441
B12: Grid Defect | C12: 9 | D12: 9 | E12: 9 | F12: 4 | G12: 10 | H12: 6 | I12: 9 | J12: 25 | K12: 13 | L12: 9 | M12: 8 | N12: 13 | O12: 20 | P12: 11 | Q12: 9 | R12: 11 | S12: 0 | T12: 6 | U12: 17 | V12: 16 | W12: 9 | X12: 14 | AG12: =+SUM(C12:AF12) -> 237
B13: Visual Crack | C13: 25 | D13: 37 | E13: 22 | F13: 27 | G13: 21 | H13: 24 | I13: 34 | J13: 38 | K13: 31 | L13: 22 | M13: 24 | N13: 32 | O13: 25 | P13: 28 | Q13: 33 | R13: 41 | S13: 0 | T13: 29 | U13: 20 | V13: 24 | W13: 21 | X13: 27 | AG13: =+SUM(C13:AF13) -> 585
B14: Dark Area | C14: 1 | D14: 1 | E14: 2 | F14: 1 | G14: 1 | H14: 4 | I14: 2 | J14: 4 | K14: 1 | L14: 0 | M14: 1 | N14: 1 | O14: 1 | P14: 2 | Q14: 1 | R14: 1 | S14: 0 | T14: 9 | U14: 2 | V14: 2 | W14: 6 | X14: 2 | AG14: =+SUM(C14:AF14) -> 45
B16: Visual Inspection report_ Sep '25
B17: Date | C17: 45901 | D17: 45902 | E17: 45903 | F17: 45904 | G17: 45905 | H17: 45906 | I17: 45907 | J17: 45908 | K17: 45909 | L17: 45910 | M17: 45911 | N17: 45912 | O17: 45913 | P17: 45914 | Q17: 45915 | R17: 45916 | S17: 45917 | T17: 45918 | U17: 45919 | V17: 45920 | W17: 45921 | X17: 45922 | Y17: 45923 | Z17: 45924 | AA17: 45925 | AB17: 45926 | AC17: 45927 | AD17: 45928 | AE17: 45929 | AF17: 45930 | AG17: Month total
B18: Total Production | C18: 2222 | D18: 2277 | E18: 2264 | F18: 2292 | G18: 2389 | H18: 2383 | I18: 2372 | J18: 2514 | K18: 2518 | L18: 1891 | M18: 2315 | N18: 2584 | O18: 2529 | P18: 2499 | Q18: 2612 | R18: 2114 | S18: 0 | T18: 2115 | U18: 2386 | V18: 2381 | W18: 2626 | X18: 2486 | AG18: =SUM(C18:AF18) -> 49769
B19: Total rejection | C19: =SUM(C21:C33) -> 93 | D19: =SUM(D21:D33) -> 118 | E19: =SUM(E21:E33) -> 157 | F19: =SUM(F21:F33) -> 133 | G19: =SUM(G21:G33) -> 141 | H19: =SUM(H21:H33) -> 113 | I19: =SUM(I21:I33) -> 104 | J19: =SUM(J21:J33) -> 107 | ... AG19: =SUM(AG21:AG33) -> 2120
A20: % | B20: Rejection % | C20: =IF(C18=0,0,(C19/C18)) -> 0.041854185 | D20: =IF(D18=0,0,(D19/D18)) -> 0.051822574 | E20: =IF(E18=0,0,(E19/E18)) -> 0.06934629 | F20: =IF(F18=0,0,(F19/F18)) -> 0.058027923 | G20: =IF(G18=0,0,(G19/G18)) -> 0.059020511 | H20: =IF(H18=0,0,(H19/H18)) -> 0.047419219 | I20: =IF(I18=0,0,(I19/I18)) -> 0.043844857 | J20: =IF(J18=0,0,(J19/J18)) -> 0.042561655 | ... AG20: =IF(AG18=0,0,(AG19/AG18)) -> 0.042596797
B21: Misalignment | C21: 5 | D21: 0 | E21: 1 | F21: 0 | G21: 3 | H21: 2 | I21: 1 | J21: 9 | K21: 0 | L21: 0 | M21: 1 | N21: 1 | O21: 4 | P21: 0 | Q21: 4 | R21: 0 | S21: 0 | T21: 2 | U21: 0 | V21: 1 | W21: 0 | X21: 5 | AG21: =+SUM(C21:AF21) -> 39
B22: Cell To Cell Touch | C22: 9 | D22: 5 | E22: 9 | F22: 27 | G22: 10 | H22: 7 | I22: 0 | J22: 2 | K22: 12 | L22: 8 | M22: 14 | N22: 14 | O22: 5 | P22: 6 | Q22: 5 | R22: 6 | S22: 0 | T22: 9 | U22: 8 | V22: 7 | W22: 10 | X22: 21 | AG22: =+SUM(C22:AF22) -> 194
B23: Chipping | C23: 1 | D23: 2 | E23: 1 | F23: 2 | G23: 0 | H23: 0 | I23: 3 | J23: 0 | K23: 5 | L23: 5 | M23: 0 | N23: 3 | O23: 2 | P23: 3 | Q23: 1 | R23: 2 | S23: 0 | T23: 3 | U23: 6 | V23: 6 | W23: 2 | X23: 4 | AG23: =+SUM(C23:AF23) -> 51
B24: Tabbing Missing | C24: 41 | D24: 70 | E24: 111 | F24: 68 | G24: 73 | H24: 70 | I24: 51 | J24: 58 | K24: 45 | L24: 35 | M24: 22 | N24: 45 | O24: 40 | P24: 40 | Q24: 53 | R24: 44 | S24: 0 | T24: 38 | U24: 62 | V24: 47 | W24: 34 | X24: 34 | AG24: =+SUM(C24:AF24) -> 1081
B25: Cell Scratch | C25: 3 | D25: 9 | E25: 10 | F25: 9 | G25: 5 | H25: 5 | I25: 10 | J25: 2 | K25: 4 | L25: 1 | M25: 5 | N25: 8 | O25: 12 | P25: 7 | Q25: 12 | R25: 1 | S25: 0 | T25: 2 | U25: 6 | V25: 11 | W25: 12 | X25: 6 | AG25: =+SUM(C25:AF25) -> 140
B26: EVA Spot | C26: 0 | D26: 0 | E26: 0 | F26: 0 | G26: 0 | H26: 0 | I26: 0 | J26: 0 | K26: 0 | L26: 0 | M26: 0 | N26: 0 | O26: 0 | P26: 0 | Q26: 0 | R26: 0 | S26: 0 | T26: 0 | U26: 0 | V26: 0 | W26: 0 | X26: 0 | AG26: =+SUM(C26:AF26) -> 0
B27: Spot On Cell | C27: 5 | D27: 7 | E27: 2 | F27: 4 | G27: 5 | H27: 2 | I27: 5 | J27: 2 | K27: 10 | L27: 1 | M27: 4 | N27: 5 | O27: 5 | P27: 4 | Q27: 3 | R27: 3 | S27: 0 | T27: 8 | U27: 5 | V27: 2 | W27: 1 | X27: 1 | AG27: =+SUM(C27:AF27) -> 84
B28: Ribbon Bend | C28: 3 | D28: 5 | E28: 1 | F28: 1 | G28: 3 | H28: 0 | I28: 1 | J28: 4 | K28: 2 | L28: 1 | M28: 1 | N28: 4 | O28: 6 | P28: 3 | Q28: 2 | R28: 3 | S28: 0 | T28: 2 | U28: 2 | V28: 2 | W28: 4 | X28: 3 | AG28: =+SUM(C28:AF28) -> 53
B29: String To String Gap | C29: 2 | D29: 1 | E29: 1 | F29: 0 | G29: 5 | H29: 1 | I29: 8 | J29: 9 | K29: 8 | L29: 6 | M29: 1 | N29: 12 | O29: 1 | P29: 4 | Q29: 3 | R29: 5 | S29: 0 | T29: 2 | U29: 5 | V29: 5 | W29: 10 | X29: 2 | AG29: =+SUM(C29:AF29) -> 91
B30: Ribbon Missing | C30: 4 | D30: 0 | E30: 1 | F30: 2 | G30: 8 | H30: 6 | I30: 3 | J30: 2 | K30: 0 | L30: 1 | M30: 1 | N30: 0 | O30: 1 | P30: 3 | Q30: 0 | R30: 3 | S30: 0 | T30: 2 | U30: 3 | V30: 12 | W30: 2 | X30: 12 | AG30: =+SUM(C30:AF30) -> 66
B31: Extra Cell | C31: 3 | D31: 5 | E31: 4 | F31: 1 | G31: 0 | H31: 4 | I31: 7 | J31: 3 | K31: 4 | L31: 1 | M31: 1 | N31: 2 | O31: 6 | P31: 1 | Q31: 5 | R31: 2 | S31: 0 | T31: 4 | U31: 3 | V31: 1 | W31: 2 | X31: 2 | AG31: =+SUM(C31:AF31) -> 61
B32: Extra Ribbon | C32: 2 | D32: 3 | E32: 2 | F32: 3 | G32: 3 | H32: 3 | I32: 4 | J32: 0 | K32: 0 | L32: 0 | M32: 1 | N32: 2 | O32: 0 | P32: 2 | Q32: 0 | R32: 1 | S32: 0 | T32: 3 | U32: 0 | V32: 0 | W32: 2 | X32: 0 | AG32: =+SUM(C32:AF32) -> 31
B33: Dust | C33: 15 | D33: 11 | E33: 14 | F33: 16 | G33: 26 | H33: 13 | I33: 11 | J33: 16 | K33: 14 | L33: 15 | M33: 7 | N33: 13 | O33: 4 | P33: 3 | Q33: 13 | R33: 3 | S33: 0 | T33: 9 | U33: 7 | V33: 6 | W33: 3 | X33: 10 | AG33: =+SUM(C33:AF33) -> 229
B36: Lam-QC Inspection report_Sep '25
B37: Date | C37: 45901 | D37: 45902 | E37: 45903 | F37: 45904 | G37: 45905 | H37: 45906 | I37: 45907 | J37: 45908 | K37: 45909 | L37: 45910 | M37: 45911 | N37: 45912 | O37: 45913 | P37: 45914 | Q37: 45915 | R37: 45916 | S37: 45917 | T37: 45918 | U37: 45919 | V37: 45920 | W37: 45921 | X37: 45922 | Y37: 45923 | Z37: 45924 | AA37: 45925 | AB37: 45926 | AC37: 45927 | AD37: 45928 | AE37: 45929 | AF37: 45930 | AG37: Month total
B38: Total Production | C38: 2402 | D38: 2336 | E38: 2425 | F38: 2371 | G38: 2384 | H38: 2407 | I38: 2476 | J38: 2697 | K38: 2465 | L38: 2065 | M38: 2350 | N38: 2564 | O38: 2600 | P38: 2650 | Q38: 2670 | R38: 2390 | S38: 0 | T38: 2230 | U38: 2415 | V38: 2605 | W38: 2640 | X38: 2575 | AG38: =SUM(C38:AF38) -> 51717
B39: Total rejection | C39: =SUM(C41:C67) -> 32 | D39: =SUM(D41:D67) -> 13 | E39: =SUM(E41:E67) -> 19 | F39: =SUM(F41:F67) -> 12 | G39: =SUM(G41:G67) -> 17 | H39: =SUM(H41:H67) -> 8 | I39: =SUM(I41:I67) -> 10 | J39: =SUM(J41:J67) -> 17 | ... AG39: =SUM(AG41:AG67) -> 361
A40: % | B40: Rejection % | C40: =IF(C38=0,0,(C39/C38)) -> 0.013322231 | D40: =IF(D38=0,0,(D39/D38)) -> 0.0055650685 | E40: =IF(E38=0,0,(E39/E38)) -> 0.0078350515 | F40: =IF(F38=0,0,(F39/F38)) -> 0.0050611556 | G40: =IF(G38=0,0,(G39/G38)) -> 0.0071308725 | H40: =IF(H38=0,0,(H39/H38)) -> 0.0033236394 | I40: =IF(I38=0,0,(I39/I38)) -> 0.0040387722 | J40: =IF(J38=0,0,(J39/J38)) -> 0.0063033 | ... AG40: =IF(AG38=0,0,(AG39/AG38)) -> 0.0069802966
B41: Bubbles On Cell | C41: 25 | D41: 3 | E41: 4 | F41: 0 | G41: 3 | H41: 0 | I41: 4 | J41: 7 | K41: 4 | L41: 3 | M41: 3 | N41: 0 | O41: 2 | P41: 11 | Q41: 14 | R41: 2 | S41: 0 | T41: 2 | U41: 0 | V41: 1 | W41: 8 | X41: 16 | AG41: =+SUM(C41:AF41) -> 112
B42: Barcode Bubbles | C42: 0 | D42: 0 | E42: 0 | F42: 2 | G42: 0 | H42: 0 | I42: 0 | J42: 0 | K42: 0 | L42: 0 | M42: 0 | N42: 0 | O42: 0 | P42: 0 | Q42: 0 | R42: 0 | S42: 0 | T42: 0 | U42: 0 | V42: 0 | W42: 0 | X42: 0 | AG42: =+SUM(C42:AF42) -> 2
B43: Cell Cutting | C43: 0 | D43: 0 | E43: 0 | F43: 0 | G43: 0 | H43: 0 | I43: 0 | J43: 0 | K43: 2 | L43: 0 | M43: 0 | N43: 0 | O43: 0 | P43: 0 | Q43: 0 | R43: 0 | S43: 0 | T43: 0 | U43: 0 | V43: 1 | W43: 0 | X43: 1 | AG43: =+SUM(C43:AF43) -> 4
B44: Cell To Cell Touch | C44: 0 | D44: 1 | E44: 4 | F44: 4 | G44: 0 | H44: 0 | I44: 0 | J44: 1 | K44: 0 | L44: 0 | M44: 7 | N44: 1 | O44: 0 | P44: 0 | Q44: 0 | R44: 0 | S44: 0 | T44: 0 | U44: 1 | V44: 0 | W44: 1 | X44: 1 | AG44: =+SUM(C44:AF44) -> 21
...

Sheet Line - 2
B2: Pre-El Inspection report_ Sep '25
B3: Date | C3: 45901 | D3: 45902 | E3: 45903 | F3: 45904 | G3: 45905 | H3: 45906 | I3: 45907 | J3: 45908 | K3: 45909 | L3: 45910 | M3: 45911 | N3: 45912 | O3: 45913 | P3: 45914 | Q3: 45915 | R3: 45916 | S3: 45917 | T3: 45918 | U3: 45919 | V3: 45920 | W3: 45921 | X3: 45922 | Y3: 45923 | Z3: 45924 | AA3: 45925 | AB3: 45926 | AC3: 45927 | AD3: 45928 | AE3: 45929 | AF3: 45930 | AG3: Month total
B4: Total Production | C4: 2676 | D4: 2544 | E4: 2762 | F4: 2725 | G4: 2601 | H4: 2622 | I4: 2695 | J4: 2708 | K4: 2579 | L4: 2549 | M4: 2705 | N4: 2612 | O4: 2935 | P4: 2854 | Q4: 2815 | R4: 2526 | S4: 0 | T4: 2633 | U4: 2644 | V4: 2807 | W4: 2735 | X4: 2708 | AG4: =SUM(C4:AF4) -> 56435
B5: Total rejection | C5: =SUM(C7:C14) -> 235 | D5: =SUM(D7:D14) -> 242 | E5: =SUM(E7:E14) -> 196 | F5: =SUM(F7:F14) -> 199 | G5: =SUM(G7:G14) -> 216 | H5: =SUM(H7:H14) -> 238 | I5: =SUM(I7:I14) -> 256 | J5: =SUM(J7:J14) -> 237 | ... AG5: =SUM(AG7:AG14) -> 4626
B6: Rejection % | C6: =IF(C4=0,0,(C5/C4)) -> 0.087817638 | D6: =IF(D4=0,0,(D5/D4)) -> 0.095125786 | E6: =IF(E4=0,0,(E5/E4)) -> 0.07096307 | F6: =IF(F4=0,0,(F5/F4)) -> 0.073027523 | G6: =IF(G4=0,0,(G5/G4)) -> 0.083044983 | H6: =IF(H4=0,0,(H5/H4)) -> 0.090770404 | I6: =IF(I4=0,0,(I5/I4)) -> 0.094990724 | J6: =IF(J4=0,0,(J5/J4)) -> 0.087518464 | ... AG6: =IF(AG4=0,0,(AG5/AG4)) -> 0.081970408
B7: Micro Crack | C7: 29 | D7: 32 | E7: 25 | F7: 20 | G7: 27 | H7: 20 | I7: 31 | J7: 32 | K7: 28 | L7: 41 | M7: 46 | N7: 24 | O7: 19 | P7: 25 | Q7: 24 | R7: 43 | S7: 0 | T7: 40 | U7: 23 | V7: 21 | W7: 28 | X7: 18 | AG7: =+SUM(C7:AF7) -> 596
B8: Dead Cell | C8: 0 | D8: 1 | E8: 1 | F8: 3 | G8: 2 | H8: 3 | I8: 0 | J8: 6 | K8: 2 | L8: 3 | M8: 0 | N8: 0 | O8: 0 | P8: 3 | Q8: 3 | R8: 0 | S8: 0 | T8: 2 | U8: 0 | V8: 3 | W8: 2 | X8: 1 | AG8: =+SUM(C8:AF8) -> 35
B9: Dry Soldering | C9: 159 | D9: 158 | E9: 130 | F9: 130 | G9: 140 | H9: 148 | I9: 153 | J9: 142 | K9: 161 | L9: 138 | M9: 85 | N9: 82 | O9: 117 | P9: 129 | Q9: 151 | R9: 116 | S9: 0 | T9: 136 | U9: 195 | V9: 140 | W9: 154 | X9: 136 | AG9: =+SUM(C9:AF9) -> 2900
B10: Poor Soldering | C10: 0 | D10: 0 | E10: 0 | F10: 0 | G10: 0 | H10: 0 | I10: 0 | J10: 0 | K10: 0 | L10: 0 | M10: 0 | N10: 0 | O10: 0 | P10: 0 | Q10: 0 | R10: 0 | S10: 0 | T10: 0 | U10: 0 | V10: 0 | W10: 0 | X10: 0 | AG10: =+SUM(C10:AF10) -> 0
B11: Cross Crack | C11: 21 | D11: 25 | E11: 20 | F11: 20 | G11: 16 | H11: 29 | I11: 29 | J11: 21 | K11: 34 | L11: 34 | M11: 27 | N11: 10 | O11: 23 | P11: 12 | Q11: 22 | R11: 26 | S11: 0 | T11: 19 | U11: 21 | V11: 22 | W11: 13 | X11: 16 | AG11: =+SUM(C11:AF11) -> 460
B12: Grid Defect | C12: 9 | D12: 4 | E12: 2 | F12: 3 | G12: 6 | H12: 3 | I12: 11 | J12: 9 | K12: 9 | L12: 3 | M12: 7 | N12: 4 | O12: 2 | P12: 17 | Q12: 5 | R12: 7 | S12: 0 | T12: 7 | U12: 8 | V12: 2 | W12: 3 | X12: 1 | AG12: =+SUM(C12:AF12) -> 122
B13: Visual Crack | C13: 16 | D13: 22 | E13: 18 | F13: 23 | G13: 25 | H13: 35 | I13: 31 | J13: 27 | K13: 34 | L13: 36 | M13: 44 | N13: 25 | O13: 24 | P13: 19 | Q13: 26 | R13: 20 | S13: 0 | T13: 25 | U13: 16 | V13: 3 | W13: 17 | X13: 15 | AG13: =+SUM(C13:AF13) -> 501
B14: Dark Area | C14: 1 | D14: 0 | E14: 0 | F14: 0 | G14: 0 | H14: 0 | I14: 1 | J14: 0 | K14: 1 | L14: 2 | M14: 1 | N14: 2 | O14: 0 | P14: 0 | Q14: 1 | R14: 2 | S14: 0 | T14: 1 | U14: 0 | V14: 0 | W14: 0 | X14: 0 | AG14: =+SUM(C14:AF14) -> 12
B16: Visual Inspection report_ Sep '25
B17: Date | C17: 45901 | D17: 45902 | E17: 45903 | F17: 45904 | G17: 45905 | H17: 45906 | I17: 45907 | J17: 45908 | K17: 45909 | L17: 45910 | M17: 45911 | N17: 45912 | O17: 45913 | P17: 45914 | Q17: 45915 | R17: 45916 | S17: 45917 | T17: 45918 | U17: 45919 | V17: 45920 | W17: 45921 | X17: 45922 | Y17: 45923 | Z17: 45924 | AA17: 45925 | AB17: 45926 | AC17: 45927 | AD17: 45928 | AE17: 45929 | AF17: 45930 | AG17: Month total
B18: Total Production | C18: 2676 | D18: 2544 | E18: 2762 | F18: 2725 | G18: 2601 | H18: 2622 | I18: 2695 | J18: 2708 | K18: 2579 | L18: 2549 | M18: 2705 | N18: 2612 | O18: 2935 | P18: 2854 | Q18: 2815 | R18: 2526 | S18: 0 | T18: 2633 | U18: 2644 | V18: 2807 | W18: 2735 | X18: 2708 | AG18: =SUM(C18:AF18) -> 56435
B19: Total rejection | C19: =SUM(C21:C33) -> 96 | D19: =SUM(D21:D33) -> 91 | E19: =SUM(E21:E33) -> 102 | F19: =SUM(F21:F33) -> 109 | G19: =SUM(G21:G33) -> 120 | H19: =SUM(H21:H33) -> 114 | I19: =SUM(I21:I33) -> 144 | J19: =SUM(J21:J33) -> 135 | ... AG19: =SUM(AG21:AG33) -> 1966
A20: % | B20: Rejection % | C20: =IF(C18=0,0,(C19/C18)) -> 0.035874439 | D20: =IF(D18=0,0,(D19/D18)) -> 0.03577044 | E20: =IF(E18=0,0,(E19/E18)) -> 0.036929761 | F20: =IF(F18=0,0,(F19/F18)) -> 0.04 | G20: =IF(G18=0,0,(G19/G18)) -> 0.046136101 | H20: =IF(H18=0,0,(H19/H18)) -> 0.043478261 | I20: =IF(I18=0,0,(I19/I18)) -> 0.053432282 | J20: =IF(J18=0,0,(J19/J18)) -> 0.04985229 | ... AG20: =IF(AG18=0,0,(AG19/AG18)) -> 0.034836538
B21: Misalignment | C21: 0 | D21: 0 | E21: 0 | F21: 0 | G21: 0 | H21: 0 | I21: 0 | J21: 0 | K21: 0 | L21: 0 | M21: 0 | N21: 0 | O21: 0 | P21: 0 | Q21: 0 | R21: 0 | S21: 0 | T21: 0 | U21: 0 | V21: 0 | W21: 0 | X21: 0 | AG21: =+SUM(C21:AF21) -> 0
B22: Cell To Cell Touch | C22: 2 | D22: 3 | E22: 8 | F22: 5 | G22: 3 | H22: 5 | I22: 3 | J22: 3 | K22: =1+1+3+9 -> 14 | L22: 2 | M22: 12 | N22: 14 | O22: 2 | P22: 8 | Q22: 4 | R22: 2 | S22: 0 | T22: 0 | U22: 3 | V22: 4 | W22: 6 | X22: 6 | AG22: =+SUM(C22:AF22) -> 109
B23: Chipping | C23: 0 | D23: 1 | E23: 0 | F23: 1 | G23: 0 | H23: 0 | I23: 0 | J23: 0 | K23: 1 | L23: 1 | M23: 1 | N23: 0 | O23: 0 | P23: 0 | Q23: 0 | R23: 2 | S23: 0 | T23: 1 | U23: 0 | V23: 0 | W23: 1 | X23: 0 | AG23: =+SUM(C23:AF23) -> 9
B24: Tabbing Missing | C24: 50 | D24: 56 | E24: 56 | F24: 58 | G24: 80 | H24: 98 | I24: 111 | J24: 87 | K24: =11+3+6+2+8+4 -> 34 | L24: 47 | M24: 60 | N24: 38 | O24: 41 | P24: 32 | Q24: 49 | R24: 45 | S24: 0 | T24: 37 | U24: 51 | V24: 55 | W24: 49 | X24: 46 | AG24: =+SUM(C24:AF24) -> 1180
B25: Cell Scratch | C25: 4 | D25: 5 | E25: 5 | F25: 9 | G25: 2 | H25: 3 | I25: 6 | J25: 5 | K25: =2+1 -> 3 | L25: 4 | M25: 5 | N25: 0 | O25: 1 | P25: 6 | Q25: 2 | R25: 3 | S25: 0 | T25: 3 | U25: 2 | V25: 5 | W25: 5 | X25: 2 | AG25: =+SUM(C25:AF25) -> 80
B26: EVA Spot | C26: 0 | D26: 1 | E26: 0 | F26: 1 | G26: 2 | H26: 0 | I26: 0 | J26: 0 | K26: 0 | L26: 0 | M26: 1 | N26: 1 | O26: 0 | P26: 0 | Q26: 0 | R26: 0 | S26: 0 | T26: 1 | U26: 0 | V26: 0 | W26: 0 | X26: 0 | AG26: =+SUM(C26:AF26) -> 7
B27: Spot On Cell | C27: 5 | D27: 6 | E27: 11 | F27: 5 | G27: 3 | H27: 0 | I27: 3 | J27: 3 | K27: =2+1+1 -> 4 | L27: 3 | M27: 3 | N27: 5 | O27: 3 | P27: 1 | Q27: 4 | R27: 1 | S27: 0 | T27: 3 | U27: 2 | V27: 4 | W27: 7 | X27: 3 | AG27: =+SUM(C27:AF27) -> 79
B28: Ribbon Bend | C28: 2 | D28: 2 | E28: 1 | F28: 1 | G28: 1 | H28: 1 | I28: 1 | J28: 1 | K28: =1+1+1 -> 3 | L28: 3 | M28: 3 | N28: 2 | O28: 1 | P28: 2 | Q28: 4 | R28: 3 | S28: 0 | T28: 1 | U28: 5 | V28: 2 | W28: 1 | X28: 1 | AG28: =+SUM(C28:AF28) -> 41
B29: String To String Gap | C29: 4 | D29: 5 | E29: 6 | F29: 12 | G29: 1 | H29: 0 | I29: 4 | J29: 13 | K29: =1+1+1+1 -> 4 | L29: 12 | M29: 6 | N29: 6 | O29: 3 | P29: 5 | Q29: 2 | R29: 2 | S29: 0 | T29: 4 | U29: 7 | V29: 3 | W29: 2 | X29: 4 | AG29: =+SUM(C29:AF29) -> 105
B30: Ribbon Missing | C30: 8 | D30: 2 | E30: 4 | F30: 3 | G30: 8 | H30: 1 | I30: 3 | J30: 0 | K30: 1 | L30: 1 | M30: 0 | N30: 2 | O30: 2 | P30: 5 | Q30: 3 | R30: 4 | S30: 0 | T30: 6 | U30: 1 | V30: 2 | W30: 5 | X30: 6 | AG30: =+SUM(C30:AF30) -> 67
B31: Extra Cell | C31: 6 | D31: 4 | E31: 4 | F31: 7 | G31: 3 | H31: 4 | I31: 4 | J31: 12 | K31: =4+2+1+1 -> 8 | L31: 4 | M31: 8 | N31: 2 | O31: 4 | P31: 6 | Q31: 4 | R31: 3 | S31: 0 | T31: 5 | U31: 6 | V31: 5 | W31: 3 | X31: 1 | AG31: =+SUM(C31:AF31) -> 103
B32: Extra Ribbon | C32: 2 | D32: 1 | E32: 0 | F32: 0 | G32: 2 | H32: 0 | I32: 2 | J32: 3 | K32: 1 | L32: 0 | M32: 0 | N32: 2 | O32: 1 | P32: 1 | Q32: 0 | R32: 1 | S32: 0 | T32: 0 | U32: 4 | V32: 0 | W32: 3 | X32: 1 | AG32: =+SUM(C32:AF32) -> 24
B33: Dust | C33: 13 | D33: 5 | E33: 7 | F33: 7 | G33: 15 | H33: 2 | I33: 7 | J33: 8 | K33: =6+3+1+1+1 -> 12 | L33: 6 | M33: 18 | N33: 5 | O33: 12 | P33: 5 | Q33: 2 | R33: 8 | S33: 0 | T33: 11 | U33: 6 | V33: 8 | W33: 3 | X33: 2 | AG33: =+SUM(C33:AF33) -> 162
B36: Lam-QC Inspection report_Sep '25
B37: Date | C37: 45901 | D37: 45902 | E37: 45903 | F37: 45904 | G37: 45905 | H37: 45906 | I37: 45907 | J37: 45908 | K37: 45909 | L37: 45910 | M37: 45911 | N37: 45912 | O37: 45913 | P37: 45914 | Q37: 45915 | R37: 45916 | S37: 45917 | T37: 45918 | U37: 45919 | V37: 45920 | W37: 45921 | X37: 45922 | Y37: 45923 | Z37: 45924 | AA37: 45925 | AB37: 45926 | AC37: 45927 | AD37: 45928 | AE37: 45929 | AF37: 45930 | AG37: Month total
B38: Total Production | C38: 2568 | D38: 2460 | E38: 2534 | F38: 2579 | G38: 2623 | H38: 2570 | I38: 2515 | J38: 2590 | K38: 2600 | L38: 2460 | M38: 2584 | N38: 2685 | O38: 2755 | P38: 2817 | Q38: 2654 | R38: 2580 | S38: 0 | T38: 2265 | U38: 2640 | V38: 2485 | W38: 2640 | X38: 2725 | AG38: =SUM(C38:AF38) -> 54329
B39: Total rejection | C39: =SUM(C41:C67) -> 7 | D39: =SUM(D41:D67) -> 18 | E39: =SUM(E41:E67) -> 15 | F39: =SUM(F41:F67) -> 18 | G39: =SUM(G41:G67) -> 19 | H39: =SUM(H41:H67) -> 21 | I39: =SUM(I41:I67) -> 23 | J39: =SUM(J41:J67) -> 16 | ... AG39: =SUM(AG41:AG67) -> 353
A40: % | B40: Rejection % | C40: =IF(C38=0,0,(C39/C38)) -> 0.0027258567 | D40: =IF(D38=0,0,(D39/D38)) -> 0.0073170732 | E40: =IF(E38=0,0,(E39/E38)) -> 0.0059194949 | F40: =IF(F38=0,0,(F39/F38)) -> 0.0069794494 | G40: =IF(G38=0,0,(G39/G38)) -> 0.0072436142 | H40: =IF(H38=0,0,(H39/H38)) -> 0.0081712062 | I40: =IF(I38=0,0,(I39/I38)) -> 0.0091451292 | J40: =IF(J38=0,0,(J39/J38)) -> 0.0061776062 | ... AG40: =IF(AG38=0,0,(AG39/AG38)) -> 0.0064974507
B41: Bubbles On Cell | C41: 3 | D41: 6 | E41: 5 | F41: 2 | G41: 2 | H41: 4 | I41: 6 | J41: 1 | K41: 7 | L41: 0 | M41: 2 | N41: 1 | O41: 2 | P41: 1 | Q41: 4 | R41: 1 | S41: 0 | T41: 3 | U41: 7 | V41: 0 | W41: 0 | X41: 2 | AG41: =+SUM(C41:AF41) -> 59
B42: Barcode Bubbles | C42: 0 | D42: 0 | E42: 0 | F42: 0 | G42: 0 | H42: 0 | I42: 0 | J42: 0 | K42: 0 | L42: 0 | M42: 0 | N42: 0 | O42: 0 | P42: 0 | Q42: 0 | R42: 0 | S42: 0 | T42: 0 | U42: 0 | V42: 0 | W42: 0 | X42: 0 | AG42: =+SUM(C42:AF42) -> 0
B43: Cell Cutting | C43: 0 | D43: 0 | E43: 0 | F43: 0 | G43: 0 | H43: 0 | I43: 0 | J43: 0 | K43: 0 | L43: 0 | M43: 0 | N43: 0 | O43: 0 | P43: 0 | Q43: 0 | R43: 0 | S43: 0 | T43: 0 | U43: 0 | V43: 0 | W43: 0 | X43: 0 | AG43: =+SUM(C43:AF43) -> 0
B44: Cell To Cell Touch | C44: 1 | D44: 1 | E44: 1 | F44: 0 | G44: 0 | H44: 0 | I44: 1 | J44: 0 | K44: 0 | L44: 2 | M44: 1 | N44: 0 | O44: 0 | P44: 1 | Q44: 0 | R44: 0 | S44: 0 | T44: 1 | U44: 1 | V44: 0 | W44: 0 | X44: 1 | AG44: =+SUM(C44:AF44) -> 11
...

Sheet MTA Export
B2: Pre-El Inspection report_August'24
B3: Date | C3: 45505 | D3: 45506 | E3: 45507 | F3: 45508 | G3: 45509 | H3: 45510 | I3: 45511 | J3: 45512 | K3: 45513 | L3: 45514 | M3: 45515 | N3: 45516 | O3: 45517 | P3: 45518 | Q3: 45519 | R3: 45520 | S3: 45521 | T3: 45522 | U3: 45523 | V3: 45524 | W3: 45525 | X3: 45526 | Y3: 45527 | Z3: 45528 | AA3: 45529 | AB3: 45530 | AC3: 45531 | AD3: 45532 | AE3: 45533 | AF3: 45534 | AG3: 45535 | AH3: Month total
B4: Total Production | C4: 0 | D4: 0 | E4: 0 | F4: 0 | G4: 0 | H4: 0 | I4: 0 | J4: 2727 | AH4: =SUM(C4:AG4) -> 2727
B5: Total rejection | C5: =SUM(C7:C14) -> 0 | D5: =SUM(D7:D14) -> 0 | E5: =SUM(E7:E14) -> 0 | F5: =SUM(F7:F14) -> 0 | G5: =SUM(G7:G14) -> 0 | H5: =SUM(H7:H14) -> 0 | I5: =SUM(I7:I14) -> 0 | J5: =SUM(J7:J14) -> 167 | ... AH5: =SUM(AH7:AH14) -> 167
B6: Rejection % | C6: =IF(C4=0,0,(C5/C4)) -> 0 | D6: =IF(D4=0,0,(D5/D4)) -> 0 | E6: =IF(E4=0,0,(E5/E4)) -> 0 | F6: =IF(F4=0,0,(F5/F4)) -> 0 | G6: =IF(G4=0,0,(G5/G4)) -> 0 | H6: =IF(H4=0,0,(H5/H4)) -> 0 | I6: =IF(I4=0,0,(I5/I4)) -> 0 | J6: =IF(J4=0,0,(J5/J4)) -> 0.061239457 | ... AH6: =IF(AH4=0,0,(AH5/AH4)) -> 0.061239457
B7: Micro Crack | C7: 0 | D7: 0 | E7: 0 | F7: 0 | G7: 0 | H7: 0 | I7: 0 | J7: =3+7+5 -> 15 | AH7: =+SUM(C7:AG7) -> 15
B8: Dead Cell | C8: 0 | D8: 0 | E8: 0 | F8: 0 | G8: 0 | H8: 0 | I8: 0 | J8: 0 | AH8: =+SUM(C8:AG8) -> 0
B9: Dry Soldering | C9: 0 | D9: 0 | E9: 0 | F9: 0 | G9: 0 | H9: 0 | I9: 0 | J9: =8+4+20+14+32 -> 78 | AH9: =+SUM(C9:AG9) -> 78
B10: Poor Soldering | C10: 0 | D10: 0 | E10: 0 | F10: 0 | G10: 0 | H10: 0 | I10: 0 | J10: 0 | AH10: =+SUM(C10:AG10) -> 0
B11: Cross Crack | C11: 0 | D11: 0 | E11: 0 | F11: 0 | G11: 0 | H11: 0 | I11: 0 | J11: =4+5+16+7+4 -> 36 | AH11: =+SUM(C11:AG11) -> 36
B12: Grid Defect | C12: 0 | D12: 0 | E12: 0 | F12: 0 | G12: 0 | H12: 0 | I12: 0 | J12: =5+5+8 -> 18 | AH12: =+SUM(C12:AG12) -> 18
B13: Visual Crack | C13: 0 | D13: 0 | E13: 0 | F13: 0 | G13: 0 | H13: 0 | I13: 0 | J13: =3+2+7+6 -> 18 | AH13: =+SUM(C13:AG13) -> 18
B14: Dark Area | C14: 0 | D14: 0 | E14: 0 | F14: 0 | G14: 0 | H14: 0 | I14: 0 | J14: 2 | AH14: =+SUM(C14:AG14) -> 2
B16: Visual Inspection report_ August'24
B17: Date | C17: 45505 | D17: 45506 | E17: 45507 | F17: 45508 | G17: 45509 | H17: 45510 | I17: 45511 | J17: 45512 | K17: 45513 | L17: 45514 | M17: 45515 | N17: 45516 | O17: 45517 | P17: 45518 | Q17: 45519 | R17: 45520 | S17: 45521 | T17: 45522 | U17: 45523 | V17: 45524 | W17: 45525 | X17: 45526 | Y17: 45527 | Z17: 45528 | AA17: 45529 | AB17: 45530 | AC17: 45531 | AD17: 45532 | AE17: 45533 | AF17: 45534 | AG17: 45535 | AH17: Month total
B18: Total Production | C18: 0 | D18: 0 | E18: 0 | F18: 0 | G18: 0 | H18: 0 | I18: 0 | J18: 2727 | AH18: =SUM(C18:AG18) -> 2727
B19: Total rejection | C19: =SUM(C21:C30) -> 0 | D19: =SUM(D21:D30) -> 0 | E19: =SUM(E21:E30) -> 0 | F19: =SUM(F21:F30) -> 0 | G19: =SUM(G21:G30) -> 0 | H19: =SUM(H21:H30) -> 0 | I19: =SUM(I21:I30) -> 0 | J19: =SUM(J21:J30) -> 11 | ... AH19: =SUM(AH21:AH30) -> 11
B20: Rejection % | C20: =IF(C18=0,0,(C19/C18)) -> 0 | D20: =IF(D18=0,0,(D19/D18)) -> 0 | E20: =IF(E18=0,0,(E19/E18)) -> 0 | F20: =IF(F18=0,0,(F19/F18)) -> 0 | G20: =IF(G18=0,0,(G19/G18)) -> 0 | H20: =IF(H18=0,0,(H19/H18)) -> 0 | I20: =IF(I18=0,0,(I19/I18)) -> 0 | J20: =IF(J18=0,0,(J19/J18)) -> 0.0040337367 | ... AH20: =IF(AH18=0,0,(AH19/AH18)) -> 0.0040337367
B21: Misalignment | C21: 0 | D21: 0 | E21: 0 | F21: 0 | G21: 0 | H21: 0 | I21: 0 | J21: 0 | AH21: =+SUM(C21:AG21) -> 0
B22: Cell To Cell Touch | C22: 0 | D22: 0 | E22: 0 | F22: 0 | G22: 0 | H22: 0 | I22: 0 | J22: 0 | AH22: =+SUM(C22:AG22) -> 0
B23: Chipping | C23: 0 | D23: 0 | E23: 0 | F23: 0 | G23: 0 | H23: 0 | I23: 0 | J23: 0 | AH23: =+SUM(C23:AG23) -> 0
B24: Tabbing Missing | C24: 0 | D24: 0 | E24: 0 | F24: 0 | G24: 0 | H24: 0 | I24: 0 | J24: 0 | AH24: =+SUM(C24:AG24) -> 0
B25: Cell Scratch | C25: 0 | D25: 0 | E25: 0 | F25: 0 | G25: 0 | H25: 0 | I25: 0 | J25: 5 | AH25: =+SUM(C25:AG25) -> 5
B26: Spot On Cell | C26: 0 | D26: 0 | E26: 0 | F26: 0 | G26: 0 | H26: 0 | I26: 0 | J26: 4 | AH26: =+SUM(C26:AG26) -> 4
B27: Ribbon Bend | C27: 0 | D27: 0 | E27: 0 | F27: 0 | G27: 0 | H27: 0 | I27: 0 | J27: 2 | AH27: =+SUM(C27:AG27) -> 2
B28: Ribbon Missing | C28: 0 | D28: 0 | E28: 0 | F28: 0 | G28: 0 | H28: 0 | I28: 0 | J28: 0 | AH28: =+SUM(C28:AG28) -> 0
B29: Extra Cell | C29: 0 | D29: 0 | E29: 0 | F29: 0 | G29: 0 | H29: 0 | I29: 0 | J29: 0 | AH29: =+SUM(C29:AG29) -> 0
B30: Dust | C30: 0 | D30: 0 | E30: 0 | F30: 0 | G30: 0 | H30: 0 | I30: 0 | J30: 0 | AH30: =+SUM(C30:AG30) -> 0
B33: Lam-QC Inspection report_August'24
B34: Date | C34: 45505 | D34: 45506 | E34: 45507 | F34: 45508 | G34: 45509 | H34: 45510 | I34: 45511 | J34: 45512 | K34: 45513 | L34: 45514 | M34: 45515 | N34: 45516 | O34: 45517 | P34: 45518 | Q34: 45519 | R34: 45520 | S34: 45521 | T34: 45522 | U34: 45523 | V34: 45524 | W34: 45525 | X34: 45526 | Y34: 45527 | Z34: 45528 | AA34: 45529 | AB34: 45530 | AC34: 45531 | AD34: 45532 | AE34: 45533 | AF34: 45534 | AG34: 45535 | AH34: Month total
B35: Total Production | C35: 0 | D35: 0 | E35: 0 | F35: 0 | G35: 0 | H35: 0 | I35: 0 | J35: 2690 | AH35: =SUM(C35:AG35) -> 2690
B36: Total rejection | C36: =SUM(C38:C57) -> 0 | D36: =SUM(D38:D57) -> 0 | E36: =SUM(E38:E57) -> 0 | F36: =SUM(F38:F57) -> 0 | G36: =SUM(G38:G57) -> 0 | H36: =SUM(H38:H57) -> 0 | I36: =SUM(I38:I57) -> 0 | J36: =SUM(J38:J57) -> 5 | ... AH36: =SUM(AH38:AH57) -> 5
B37: Rejection % | C37: =IF(C35=0,0,(C36/C35)) -> 0 | D37: =IF(D35=0,0,(D36/D35)) -> 0 | E37: =IF(E35=0,0,(E36/E35)) -> 0 | F37: =IF(F35=0,0,(F36/F35)) -> 0 | G37: =IF(G35=0,0,(G36/G35)) -> 0 | H37: =IF(H35=0,0,(H36/H35)) -> 0 | I37: =IF(I35=0,0,(I36/I35)) -> 0 | J37: =IF(J35=0,0,(J36/J35)) -> 0.0018587361 | ... AH37: =IF(AH35=0,0,(AH36/AH35)) -> 0.0018587361
B38: Bubbles On Cell | C38: 0 | D38: 0 | E38: 0 | F38: 0 | G38: 0 | H38: 0 | I38: 0 | J38: 4 | AH38: =+SUM(C38:AG38) -> 4
B39: Barcode Bubbles | C39: 0 | D39: 0 | E39: 0 | F39: 0 | G39: 0 | H39: 0 | I39: 0 | J39: 0 | AH39: =+SUM(C39:AG39) -> 0
B40: Cell To Cell Touch | C40: 0 | D40: 0 | E40: 0 | F40: 0 | G40: 0 | H40: 0 | I40: 0 | J40: 0 | AH40: =+SUM(C40:AG40) -> 0
B41: Cell Crack | C41: 0 | D41: 0 | E41: 0 | F41: 0 | G41: 0 | H41: 0 | I41: 0 | J41: 0 | AH41: =+SUM(C41:AG41) -> 0
B42: Cell Chipping | C42: 0 | D42: 0 | E42: 0 | F42: 0 | G42: 0 | H42: 0 | I42: 0 | J42: 0 | AH42: =+SUM(C42:AG42) -> 0
B43: Cell Scratch | C43: 0 | D43: 0 | E43: 0 | F43: 0 | G43: 0 | H43: 0 | I43: 0 | J43: 0 | AH43: =+SUM(C43:AG43) -> 0
B44: D - Lam | C44: 0 | D44: 0 | E44: 0 | F44: 0 | G44: 0 | H44: 0 | I44: 0 | J44: 0 | AH44: =+SUM(C44:AG44) -> 0
...

Sheet Graph
B22: Defects | C22: Root Cause | D22: Action Taken
B23: Visual Crack | C23: Main reason for Cell Cracks 1.Z bend Misplacement 2.Ribbon Bend 3.Sliipage from Pre-EL 4.Laminator problem
B24: Cell Chipping | C24: 1. Slippage from stringer-5 and laser cutting also
B25: Spot On Cell | C25: 1.Slipage from pre-lam
B26: Bubbles On Cell | C26: 1.Bubbles on cell were coming for dust which was creating from front EVA loader
B27: Micro Crack | C27: 1.J/B Rework 2.Corner gap and frame rework
B28: Poor Soldering | C28: 1.Slippage from Pre-lam 2.Changed cell were not soldered properly
